$ go test -v a_test.go=== RUN TestXXX a_test.go:9: exit--- FAIL: TestXXX (0.00s)panic: unexpected call to os.Exit(0) during test [recovered]  panic: unexpected call to os.Exit(0) during testgoroutine 18 [running]:testing.tRunner.func1.2(0x51b920, 0x56cc28)  /usr/local/go/src/testing/testing.go:1144 +0x332testing.tRunner.func1(0xc000082600)  /usr/local/go/src/testing/testing.go:1147 +0x4b6panic(0x51b920, 0x56cc28)  /usr/local/go/src/runtime/panic.go:965 +0x1b9os.Exit(0x0)  /usr/local/go/src/os/proc.go:68 +0x6dcommand-line-arguments.TestXXX(0xc000082600)  /tmp/a_test.go:10 +0x76testing.tRunner(0xc000082600, 0x54df18)  /usr/local/go/src/testing/testing.go:1194 +0xefcreated by testing.(*T).Run  /usr/local/go/src/testing/testing.go:1239 +0x2b3FAIL command-line-arguments 0.004sFAIL